[27/Mar/2018 13:05:33] "POST /users/login HTTP/1.1" 200 57
[27/Mar/2018 13:05:48] "POST /images HTTP/1.1" 200 501
[27/Mar/2018 13:05:48] "POST /images HTTP/1.1" 200 501
[27/Mar/2018 13:12:18] "POST /images HTTP/1.1" 200 501
[27/Mar/2018 13:12:19] "POST /images HTTP/1.1" 200 501
[27/Mar/2018 13:16:39] "POST /images HTTP/1.1" 200 501
[27/Mar/2018 13:16:40] "POST /images HTTP/1.1" 200 501
[27/Mar/2018 13:34:10] "POST /images HTTP/1.1" 200 501
[27/Mar/2018 13:40:16] "POST /images HTTP/1.1" 200 501
[27/Mar/2018 13:40:17] "POST /images HTTP/1.1" 200 501
[27/Mar/2018 14:37:28] "POST /images HTTP/1.1" 200 501
[27/Mar/2018 14:38:15] "POST /images HTTP/1.1" 200 501
[27/Mar/2018 14:39:01] "POST /images HTTP/1.1" 200 501
[27/Mar/2018 14:39:02] "POST /images HTTP/1.1" 200 501
[27/Mar/2018 14:39:47] "POST /images HTTP/1.1" 200 501
[27/Mar/2018 14:39:57] "POST /images HTTP/1.1" 200 501
[27/Mar/2018 14:41:39] "POST /images HTTP/1.1" 200 501
[27/Mar/2018 14:41:41] "POST /images HTTP/1.1" 200 501
[27/Mar/2018 14:49:01] "POST /images HTTP/1.1" 200 501
[27/Mar/2018 14:49:01] "POST /images HTTP/1.1" 200 501
[27/Mar/2018 14:51:48] "POST /images HTTP/1.1" 200 501
Internal Server Error: /images
Traceback (most recent call last):
  File "/usr/local/lib/python3.5/dist-packages/django/core/handlers/exception.py", line 35, in inner
    response = get_response(request)
  File "/usr/local/lib/python3.5/dist-packages/django/core/handlers/base.py", line 128, in _get_response
    response = self.process_exception_by_middleware(e, request)
  File "/usr/local/lib/python3.5/dist-packages/django/core/handlers/base.py", line 126, in _get_response
    response = wrapped_callback(request, *callback_args, **callback_kwargs)
  File "/root/sd_project/sd_project/restful.py", line 19, in _func
    return handler(request)
  File "/root/sd_project/sd_project/auth.py", line 21, in _func
    return func(self, request)
  File "/root/sd_project/sd_project/image.py", line 230, in put
    image = ImageStorage.objects.get(id=image_id)
  File "/usr/local/lib/python3.5/dist-packages/django/db/models/manager.py", line 82, in manager_method
    return getattr(self.get_queryset(), name)(*args, **kwargs)
  File "/usr/local/lib/python3.5/dist-packages/django/db/models/query.py", line 394, in get
    clone = self.filter(*args, **kwargs)
  File "/usr/local/lib/python3.5/dist-packages/django/db/models/query.py", line 836, in filter
    return self._filter_or_exclude(False, *args, **kwargs)
  File "/usr/local/lib/python3.5/dist-packages/django/db/models/query.py", line 854, in _filter_or_exclude
    clone.query.add_q(Q(*args, **kwargs))
  File "/usr/local/lib/python3.5/dist-packages/django/db/models/sql/query.py", line 1253, in add_q
    clause, _ = self._add_q(q_object, self.used_aliases)
  File "/usr/local/lib/python3.5/dist-packages/django/db/models/sql/query.py", line 1277, in _add_q
    split_subq=split_subq,
  File "/usr/local/lib/python3.5/dist-packages/django/db/models/sql/query.py", line 1215, in build_filter
    condition = self.build_lookup(lookups, col, value)
  File "/usr/local/lib/python3.5/dist-packages/django/db/models/sql/query.py", line 1085, in build_lookup
    lookup = lookup_class(lhs, rhs)
  File "/usr/local/lib/python3.5/dist-packages/django/db/models/lookups.py", line 18, in __init__
    self.rhs = self.get_prep_lookup()
  File "/usr/local/lib/python3.5/dist-packages/django/db/models/lookups.py", line 68, in get_prep_lookup
    return self.lhs.output_field.get_prep_value(self.rhs)
  File "/usr/local/lib/python3.5/dist-packages/django/db/models/fields/__init__.py", line 947, in get_prep_value
    return int(value)
ValueError: invalid literal for int() with base 10: '52.png'
[27/Mar/2018 14:51:49] "PUT /images HTTP/1.1" 500 123113
[27/Mar/2018 15:03:55] "POST /images HTTP/1.1" 200 501
Internal Server Error: /images
Traceback (most recent call last):
  File "/usr/local/lib/python3.5/dist-packages/django/core/handlers/exception.py", line 35, in inner
    response = get_response(request)
  File "/usr/local/lib/python3.5/dist-packages/django/core/handlers/base.py", line 128, in _get_response
    response = self.process_exception_by_middleware(e, request)
  File "/usr/local/lib/python3.5/dist-packages/django/core/handlers/base.py", line 126, in _get_response
    response = wrapped_callback(request, *callback_args, **callback_kwargs)
  File "/root/sd_project/sd_project/restful.py", line 19, in _func
    return handler(request)
  File "/root/sd_project/sd_project/auth.py", line 21, in _func
    return func(self, request)
  File "/root/sd_project/sd_project/image.py", line 230, in put
    image = ImageStorage.objects.get(id=image_id)
  File "/usr/local/lib/python3.5/dist-packages/django/db/models/manager.py", line 82, in manager_method
    return getattr(self.get_queryset(), name)(*args, **kwargs)
  File "/usr/local/lib/python3.5/dist-packages/django/db/models/query.py", line 394, in get
    clone = self.filter(*args, **kwargs)
  File "/usr/local/lib/python3.5/dist-packages/django/db/models/query.py", line 836, in filter
    return self._filter_or_exclude(False, *args, **kwargs)
  File "/usr/local/lib/python3.5/dist-packages/django/db/models/query.py", line 854, in _filter_or_exclude
    clone.query.add_q(Q(*args, **kwargs))
  File "/usr/local/lib/python3.5/dist-packages/django/db/models/sql/query.py", line 1253, in add_q
    clause, _ = self._add_q(q_object, self.used_aliases)
  File "/usr/local/lib/python3.5/dist-packages/django/db/models/sql/query.py", line 1277, in _add_q
    split_subq=split_subq,
  File "/usr/local/lib/python3.5/dist-packages/django/db/models/sql/query.py", line 1215, in build_filter
    condition = self.build_lookup(lookups, col, value)
  File "/usr/local/lib/python3.5/dist-packages/django/db/models/sql/query.py", line 1085, in build_lookup
    lookup = lookup_class(lhs, rhs)
  File "/usr/local/lib/python3.5/dist-packages/django/db/models/lookups.py", line 18, in __init__
    self.rhs = self.get_prep_lookup()
  File "/usr/local/lib/python3.5/dist-packages/django/db/models/lookups.py", line 68, in get_prep_lookup
    return self.lhs.output_field.get_prep_value(self.rhs)
  File "/usr/local/lib/python3.5/dist-packages/django/db/models/fields/__init__.py", line 947, in get_prep_value
    return int(value)
ValueError: invalid literal for int() with base 10: '53.png'
[27/Mar/2018 15:03:56] "PUT /images HTTP/1.1" 500 123113
[27/Mar/2018 15:07:53] "POST /images HTTP/1.1" 200 501
Internal Server Error: /images
Traceback (most recent call last):
  File "/usr/local/lib/python3.5/dist-packages/django/core/handlers/exception.py", line 35, in inner
    response = get_response(request)
  File "/usr/local/lib/python3.5/dist-packages/django/core/handlers/base.py", line 128, in _get_response
    response = self.process_exception_by_middleware(e, request)
  File "/usr/local/lib/python3.5/dist-packages/django/core/handlers/base.py", line 126, in _get_response
    response = wrapped_callback(request, *callback_args, **callback_kwargs)
  File "/root/sd_project/sd_project/restful.py", line 19, in _func
    return handler(request)
  File "/root/sd_project/sd_project/auth.py", line 21, in _func
    return func(self, request)
  File "/root/sd_project/sd_project/image.py", line 230, in put
    image = ImageStorage.objects.get(id=image_id)
  File "/usr/local/lib/python3.5/dist-packages/django/db/models/manager.py", line 82, in manager_method
    return getattr(self.get_queryset(), name)(*args, **kwargs)
  File "/usr/local/lib/python3.5/dist-packages/django/db/models/query.py", line 394, in get
    clone = self.filter(*args, **kwargs)
  File "/usr/local/lib/python3.5/dist-packages/django/db/models/query.py", line 836, in filter
    return self._filter_or_exclude(False, *args, **kwargs)
  File "/usr/local/lib/python3.5/dist-packages/django/db/models/query.py", line 854, in _filter_or_exclude
    clone.query.add_q(Q(*args, **kwargs))
  File "/usr/local/lib/python3.5/dist-packages/django/db/models/sql/query.py", line 1253, in add_q
    clause, _ = self._add_q(q_object, self.used_aliases)
  File "/usr/local/lib/python3.5/dist-packages/django/db/models/sql/query.py", line 1277, in _add_q
    split_subq=split_subq,
  File "/usr/local/lib/python3.5/dist-packages/django/db/models/sql/query.py", line 1215, in build_filter
    condition = self.build_lookup(lookups, col, value)
  File "/usr/local/lib/python3.5/dist-packages/django/db/models/sql/query.py", line 1085, in build_lookup
    lookup = lookup_class(lhs, rhs)
  File "/usr/local/lib/python3.5/dist-packages/django/db/models/lookups.py", line 18, in __init__
    self.rhs = self.get_prep_lookup()
  File "/usr/local/lib/python3.5/dist-packages/django/db/models/lookups.py", line 68, in get_prep_lookup
    return self.lhs.output_field.get_prep_value(self.rhs)
  File "/usr/local/lib/python3.5/dist-packages/django/db/models/fields/__init__.py", line 947, in get_prep_value
    return int(value)
ValueError: invalid literal for int() with base 10: '54.png'
[27/Mar/2018 15:07:54] "PUT /images HTTP/1.1" 500 123113
[27/Mar/2018 15:09:58] code 400, message Bad HTTP/0.9 request type ('\x03\x00\x00+&à\x00\x00\x00\x00\x00Cookie:')
[27/Mar/2018 15:09:58] "  +&à     Cookie: mstshash=hello" 400 -
[27/Mar/2018 15:10:03] "POST /images HTTP/1.1" 200 501
Internal Server Error: /images
Traceback (most recent call last):
  File "/usr/local/lib/python3.5/dist-packages/django/core/handlers/exception.py", line 35, in inner
    response = get_response(request)
  File "/usr/local/lib/python3.5/dist-packages/django/core/handlers/base.py", line 128, in _get_response
    response = self.process_exception_by_middleware(e, request)
  File "/usr/local/lib/python3.5/dist-packages/django/core/handlers/base.py", line 126, in _get_response
    response = wrapped_callback(request, *callback_args, **callback_kwargs)
  File "/root/sd_project/sd_project/restful.py", line 19, in _func
    return handler(request)
  File "/root/sd_project/sd_project/auth.py", line 21, in _func
    return func(self, request)
  File "/root/sd_project/sd_project/image.py", line 230, in put
    image = ImageStorage.objects.get(id=image_id)
  File "/usr/local/lib/python3.5/dist-packages/django/db/models/manager.py", line 82, in manager_method
    return getattr(self.get_queryset(), name)(*args, **kwargs)
  File "/usr/local/lib/python3.5/dist-packages/django/db/models/query.py", line 394, in get
    clone = self.filter(*args, **kwargs)
  File "/usr/local/lib/python3.5/dist-packages/django/db/models/query.py", line 836, in filter
    return self._filter_or_exclude(False, *args, **kwargs)
  File "/usr/local/lib/python3.5/dist-packages/django/db/models/query.py", line 854, in _filter_or_exclude
    clone.query.add_q(Q(*args, **kwargs))
  File "/usr/local/lib/python3.5/dist-packages/django/db/models/sql/query.py", line 1253, in add_q
    clause, _ = self._add_q(q_object, self.used_aliases)
  File "/usr/local/lib/python3.5/dist-packages/django/db/models/sql/query.py", line 1277, in _add_q
    split_subq=split_subq,
  File "/usr/local/lib/python3.5/dist-packages/django/db/models/sql/query.py", line 1215, in build_filter
    condition = self.build_lookup(lookups, col, value)
  File "/usr/local/lib/python3.5/dist-packages/django/db/models/sql/query.py", line 1085, in build_lookup
    lookup = lookup_class(lhs, rhs)
  File "/usr/local/lib/python3.5/dist-packages/django/db/models/lookups.py", line 18, in __init__
    self.rhs = self.get_prep_lookup()
  File "/usr/local/lib/python3.5/dist-packages/django/db/models/lookups.py", line 68, in get_prep_lookup
    return self.lhs.output_field.get_prep_value(self.rhs)
  File "/usr/local/lib/python3.5/dist-packages/django/db/models/fields/__init__.py", line 947, in get_prep_value
    return int(value)
ValueError: invalid literal for int() with base 10: '55.png'
[27/Mar/2018 15:10:04] "PUT /images HTTP/1.1" 500 123113
[27/Mar/2018 15:11:17] "POST /images HTTP/1.1" 200 501
Internal Server Error: /images
Traceback (most recent call last):
  File "/usr/local/lib/python3.5/dist-packages/django/core/handlers/exception.py", line 35, in inner
    response = get_response(request)
  File "/usr/local/lib/python3.5/dist-packages/django/core/handlers/base.py", line 128, in _get_response
    response = self.process_exception_by_middleware(e, request)
  File "/usr/local/lib/python3.5/dist-packages/django/core/handlers/base.py", line 126, in _get_response
    response = wrapped_callback(request, *callback_args, **callback_kwargs)
  File "/root/sd_project/sd_project/restful.py", line 19, in _func
    return handler(request)
  File "/root/sd_project/sd_project/auth.py", line 21, in _func
    return func(self, request)
  File "/root/sd_project/sd_project/image.py", line 230, in put
    image = ImageStorage.objects.get(id=image_id)
  File "/usr/local/lib/python3.5/dist-packages/django/db/models/manager.py", line 82, in manager_method
    return getattr(self.get_queryset(), name)(*args, **kwargs)
  File "/usr/local/lib/python3.5/dist-packages/django/db/models/query.py", line 394, in get
    clone = self.filter(*args, **kwargs)
  File "/usr/local/lib/python3.5/dist-packages/django/db/models/query.py", line 836, in filter
    return self._filter_or_exclude(False, *args, **kwargs)
  File "/usr/local/lib/python3.5/dist-packages/django/db/models/query.py", line 854, in _filter_or_exclude
    clone.query.add_q(Q(*args, **kwargs))
  File "/usr/local/lib/python3.5/dist-packages/django/db/models/sql/query.py", line 1253, in add_q
    clause, _ = self._add_q(q_object, self.used_aliases)
  File "/usr/local/lib/python3.5/dist-packages/django/db/models/sql/query.py", line 1277, in _add_q
    split_subq=split_subq,
  File "/usr/local/lib/python3.5/dist-packages/django/db/models/sql/query.py", line 1215, in build_filter
    condition = self.build_lookup(lookups, col, value)
  File "/usr/local/lib/python3.5/dist-packages/django/db/models/sql/query.py", line 1085, in build_lookup
    lookup = lookup_class(lhs, rhs)
  File "/usr/local/lib/python3.5/dist-packages/django/db/models/lookups.py", line 18, in __init__
    self.rhs = self.get_prep_lookup()
  File "/usr/local/lib/python3.5/dist-packages/django/db/models/lookups.py", line 68, in get_prep_lookup
    return self.lhs.output_field.get_prep_value(self.rhs)
  File "/usr/local/lib/python3.5/dist-packages/django/db/models/fields/__init__.py", line 947, in get_prep_value
    return int(value)
ValueError: invalid literal for int() with base 10: '56.png'
[27/Mar/2018 15:11:18] "PUT /images HTTP/1.1" 500 123113
[27/Mar/2018 15:11:31] "POST /images HTTP/1.1" 200 501
Internal Server Error: /images
Traceback (most recent call last):
  File "/usr/local/lib/python3.5/dist-packages/django/core/handlers/exception.py", line 35, in inner
    response = get_response(request)
  File "/usr/local/lib/python3.5/dist-packages/django/core/handlers/base.py", line 128, in _get_response
    response = self.process_exception_by_middleware(e, request)
  File "/usr/local/lib/python3.5/dist-packages/django/core/handlers/base.py", line 126, in _get_response
    response = wrapped_callback(request, *callback_args, **callback_kwargs)
  File "/root/sd_project/sd_project/restful.py", line 19, in _func
    return handler(request)
  File "/root/sd_project/sd_project/auth.py", line 21, in _func
    return func(self, request)
  File "/root/sd_project/sd_project/image.py", line 230, in put
    image = ImageStorage.objects.get(id=image_id)
  File "/usr/local/lib/python3.5/dist-packages/django/db/models/manager.py", line 82, in manager_method
    return getattr(self.get_queryset(), name)(*args, **kwargs)
  File "/usr/local/lib/python3.5/dist-packages/django/db/models/query.py", line 394, in get
    clone = self.filter(*args, **kwargs)
  File "/usr/local/lib/python3.5/dist-packages/django/db/models/query.py", line 836, in filter
    return self._filter_or_exclude(False, *args, **kwargs)
  File "/usr/local/lib/python3.5/dist-packages/django/db/models/query.py", line 854, in _filter_or_exclude
    clone.query.add_q(Q(*args, **kwargs))
  File "/usr/local/lib/python3.5/dist-packages/django/db/models/sql/query.py", line 1253, in add_q
    clause, _ = self._add_q(q_object, self.used_aliases)
  File "/usr/local/lib/python3.5/dist-packages/django/db/models/sql/query.py", line 1277, in _add_q
    split_subq=split_subq,
  File "/usr/local/lib/python3.5/dist-packages/django/db/models/sql/query.py", line 1215, in build_filter
    condition = self.build_lookup(lookups, col, value)
  File "/usr/local/lib/python3.5/dist-packages/django/db/models/sql/query.py", line 1085, in build_lookup
    lookup = lookup_class(lhs, rhs)
  File "/usr/local/lib/python3.5/dist-packages/django/db/models/lookups.py", line 18, in __init__
    self.rhs = self.get_prep_lookup()
  File "/usr/local/lib/python3.5/dist-packages/django/db/models/lookups.py", line 68, in get_prep_lookup
    return self.lhs.output_field.get_prep_value(self.rhs)
  File "/usr/local/lib/python3.5/dist-packages/django/db/models/fields/__init__.py", line 947, in get_prep_value
    return int(value)
ValueError: invalid literal for int() with base 10: '57.png'
[27/Mar/2018 15:11:32] "PUT /images HTTP/1.1" 500 123113
[27/Mar/2018 15:13:15] "POST /images HTTP/1.1" 200 501
Internal Server Error: /images
Traceback (most recent call last):
  File "/usr/local/lib/python3.5/dist-packages/django/core/handlers/exception.py", line 35, in inner
    response = get_response(request)
  File "/usr/local/lib/python3.5/dist-packages/django/core/handlers/base.py", line 128, in _get_response
    response = self.process_exception_by_middleware(e, request)
  File "/usr/local/lib/python3.5/dist-packages/django/core/handlers/base.py", line 126, in _get_response
    response = wrapped_callback(request, *callback_args, **callback_kwargs)
  File "/root/sd_project/sd_project/restful.py", line 19, in _func
    return handler(request)
  File "/root/sd_project/sd_project/auth.py", line 21, in _func
    return func(self, request)
  File "/root/sd_project/sd_project/image.py", line 230, in put
    image = ImageStorage.objects.get(id=image_id)
  File "/usr/local/lib/python3.5/dist-packages/django/db/models/manager.py", line 82, in manager_method
    return getattr(self.get_queryset(), name)(*args, **kwargs)
  File "/usr/local/lib/python3.5/dist-packages/django/db/models/query.py", line 394, in get
    clone = self.filter(*args, **kwargs)
  File "/usr/local/lib/python3.5/dist-packages/django/db/models/query.py", line 836, in filter
    return self._filter_or_exclude(False, *args, **kwargs)
  File "/usr/local/lib/python3.5/dist-packages/django/db/models/query.py", line 854, in _filter_or_exclude
    clone.query.add_q(Q(*args, **kwargs))
  File "/usr/local/lib/python3.5/dist-packages/django/db/models/sql/query.py", line 1253, in add_q
    clause, _ = self._add_q(q_object, self.used_aliases)
  File "/usr/local/lib/python3.5/dist-packages/django/db/models/sql/query.py", line 1277, in _add_q
    split_subq=split_subq,
  File "/usr/local/lib/python3.5/dist-packages/django/db/models/sql/query.py", line 1215, in build_filter
    condition = self.build_lookup(lookups, col, value)
  File "/usr/local/lib/python3.5/dist-packages/django/db/models/sql/query.py", line 1085, in build_lookup
    lookup = lookup_class(lhs, rhs)
  File "/usr/local/lib/python3.5/dist-packages/django/db/models/lookups.py", line 18, in __init__
    self.rhs = self.get_prep_lookup()
  File "/usr/local/lib/python3.5/dist-packages/django/db/models/lookups.py", line 68, in get_prep_lookup
    return self.lhs.output_field.get_prep_value(self.rhs)
  File "/usr/local/lib/python3.5/dist-packages/django/db/models/fields/__init__.py", line 947, in get_prep_value
    return int(value)
ValueError: invalid literal for int() with base 10: '58.png'
[27/Mar/2018 15:13:15] "PUT /images HTTP/1.1" 500 123113
[27/Mar/2018 15:20:43] "POST /images HTTP/1.1" 200 501
[27/Mar/2018 15:20:43] "POST /images HTTP/1.1" 200 501
[27/Mar/2018 15:21:18] "POST /images HTTP/1.1" 200 501
[27/Mar/2018 15:21:18] "POST /images HTTP/1.1" 200 501
[27/Mar/2018 15:22:04] "POST /images HTTP/1.1" 200 501
[27/Mar/2018 15:22:07] "POST /images HTTP/1.1" 200 501
[27/Mar/2018 15:22:25] "POST /images HTTP/1.1" 200 501
[27/Mar/2018 15:22:26] "POST /images HTTP/1.1" 200 501
Not Found: /http:/www.baidu.com/cache/global/img/gs.gif
[27/Mar/2018 21:20:15] "GET http://www.baidu.com/cache/global/img/gs.gif HTTP/1.1" 404 1738
Not Found: /struts2-rest-showcase/orders.xhtml
[27/Mar/2018 21:48:35] "GET /struts2-rest-showcase/orders.xhtml HTTP/1.1" 404 2480
Not Found: /index.action
[27/Mar/2018 21:48:36] "GET /index.action HTTP/1.1" 404 2414
Not Found: /index.do
[27/Mar/2018 21:48:36] "GET /index.do HTTP/1.1" 404 2402
Not Found: /
[28/Mar/2018 00:51:54] "GET / HTTP/1.1" 404 2362
[28/Mar/2018 01:19:21] "POST /users/login HTTP/1.1" 200 57
